Workbook
Name ListaCorretores: CADASTRO!$B$3:$B$31
Name ListaEmpreendimentos: CADASTRO!$A$3:$A$31
Name ListaOrigem: CADASTRO!$C$3:$C$31
Name Tbl_cadastro: Table1[#All]

Sheet INTRUÇÃO
B1: MANUAL DE USO DO DASHBOARD
B5: 1. ONDE PREENCHER:
B6: - Cadastre novos corretores/serviços na aba "Cadastro".
B7: - Insira os atendimentos/vendas na aba "Base_Dados".
B10: 2. O QUE NÃO ALTERAR:
B11: - Nunca altere as abas "Tratamento", "Indicadores" ou "Dashboard".
B12: - Elas possuem fórmulas automáticas de consolidação.
B15: 3. COMO ATUALIZAR:
B16: - Após inserir novos dados na Base, aperte Ctrl + Alt + F5.

Sheet CADASTRO
A1: CADASTRO
A2: EMPREENDIMENTO | B2: CORRETOR(A) | C2: ORIGEM | D2: STATUS
A3: Residencial Horizons | B3: Carlos Silva | C3: Meta Ads | D3: Lead
A4: Edifício Apex Tower | B4: Ana Souza | C4: Google Ads | D4: Contato Feito
A5: Condomínio Ville | B5: Roberto Lima | C5: Portal Imobiliário | D5: Visita Agendada
A6: Solar das Palmeiras | B6: Mariana Costa | C6: Indicação | D6: Proposta Enviada
A7: Grand Valley Resort | B7: Lucas Mendes | C7: Passante / Placa | D7: Venda Fechada
A8: Horizon City | B8: Juliana Paes | C8: WhatsApp Direct | D8: Perdido
A9: Villa Bella | B9: Fernando Dias | C9: Feira Imobiliária

Sheet BASE_DADOS
A1: BASE DE DADOS
A2: DATA | B2: EMPRENDIMENTO | C2: CLIENTE | D2: CORRETOR(A) | E2: ORIGEM | F2: VALOR PEDIDO | G2: STATUS | H2: VALOR VENDA | I2: Mês | J2: Ano
A3: 46083 | B3: Grand Valley Resort | C3: João Pedro Silva | D3: Carlos Silva | E3: Meta Ads | F3: R$ 450.000 | G3: 5. Venda Fechada | H3: 440000 | I3: Março | J3: 2026
A4: 46144 | B4: Edifício Apex Tower | C4: Maria Clara Santos | D4: Ana Souza | E4: Google Ads | F4: R$ 850.000 | G4: 3. Visita Agendada | H4: - | I4: Maio | J4: 2026
A5: 46144 | B5: Condomínio Ville | C5: Lucas Oliveira | D5: Roberto Lima | E5: Portal Imobiliário | F5: R$ 320.000 | G5: 1. Lead | H5: - | I5: Maio | J5: 2026
A6: 46144 | B6: Solar das Palmeiras | C6: Beatrys Rocha | D6: Mariana Costa | E6: Indicação | F6: R$ 680.000 | G6: 4. Proposta Enviada | H6: - | I6: Maio | J6: 2026
A7: 46144 | B7: Grand Valley Resort | C7: Gabriel Souza | D7: Lucas Mendes | E7: Meta Ads | F7: R$ 1.200.000 | G7: 5. Venda Fechada | H7: 1150000 | I7: Maio | J7: 2026
A8: 46148 | B8: Residencial Horizons | C8: Patricia Lima | D8: Carlos Silva | E8: Google Ads | F8: R$ 450.000 | G8: 6. Perdido | H8: - | I8: Maio | J8: 2026
A9: 46149 | B9: Horizon City | C9: Rodrigo Alves | D9: Juliana Paes | E9: Passante / Placa | F9: R$ 510.000 | G9: 2. Contato Feito | H9: - | I9: Maio | J9: 2026
A10: 46150 | B10: Villa Bella | C10: Camila Ribeiro | D10: Fernando Dias | E10: Meta Ads | F10: R$ 290.000 | G10: 1. Lead | H10: - | I10: Maio | J10: 2026
A11: 46151 | B11: Edifício Apex Tower | C11: Marcelo Castro | D11: Ana Souza | E11: Indicação | F11: R$ 850.000 | G11: 4. Proposta Enviada | H11: - | I11: Maio | J11: 2026
A12: 46152 | B12: Condomínio Ville | C12: Fernanda Gomes | D12: Roberto Lima | E12: Meta Ads | F12: R$ 320.000 | G12: 6. Perdido | H12: - | I12: Maio | J12: 2026
A13: 46153 | B13: Solar das Palmeiras | C13: André Martins | D13: Mariana Costa | E13: Google Ads | F13: R$ 680.000 | G13: 3. Visita Agendada | H13: - | I13: Maio | J13: 2026
A14: 46154 | B14: Grand Valley Resort | C14: Vanessa Dias | D14: Lucas Mendes | E14: Portal Imobiliário | F14: R$ 1.200.000 | G14: 1. Lead | H14: - | I14: Maio | J14: 2026
A15: 46155 | B15: Residencial Horizons | C15: Thiago Nunes | D15: Carlos Silva | E15: Meta Ads | F15: R$ 450.000 | G15: 5. Venda Fechada | H15: 450000 | I15: Maio | J15: 2026
A16: 46164 | B16: Horizon City | C16: Larissa Mello | D16: Juliana Paes | E16: WhatsApp Direct | F16: R$ 510.000 | G16: 3. Visita Agendada | H16: - | I16: Maio | J16: 2026
A17: 46164 | B17: Villa Bella | C17: Diego Fernandes | D17: Fernando Dias | E17: Google Ads | F17: R$ 290.000 | G17: 2. Contato Feito | H17: - | I17: Maio | J17: 2026
A18: 46164 | B18: Edifício Apex Tower | C18: Bruno Carvalho | D18: Ana Souza | E18: Meta Ads | F18: R$ 850.000 | G18: 1. Lead | H18: - | I18: Maio | J18: 2026
A19: 46164 | B19: Condomínio Ville | C19: Renata Silveira | D19: Roberto Lima | E19: Indicação | F19: R$ 320.000 | G19: 1. Lead | H19: - | I19: Maio | J19: 2026
A20: 46164 | B20: Solar das Palmeiras | C20: Caio Henrique | D20: Mariana Costa | E20: Meta Ads | F20: R$ 680.000 | G20: 1. Lead | H20: - | I20: Maio | J20: 2026
A21: 46164 | B21: Grand Valley Resort | C21: Tatiana Lopes | D21: Lucas Mendes | E21: Google Ads | F21: R$ 1.200.000 | G21: 6. Perdido | H21: - | I21: Maio | J21: 2026
A22: 46164 | B22: Residencial Horizons | C22: Fabio Junqueira | D22: Carlos Silva | E22: Portal Imobiliário | F22: R$ 450.000 | G22: 2. Contato Feito | H22: - | I22: Maio | J22: 2026
A23: 46164 | B23: Horizon City | C23: Leticia Prado | D23: Juliana Paes | E23: Meta Ads | F23: R$ 510.000 | G23: 4. Proposta Enviada | H23: - | I23: Maio | J23: 2026
A24: 46164 | B24: Villa Bella | C24: Igor Barbosa | D24: Fernando Dias | E24: Indicação | F24: R$ 290.000 | G24: 5. Venda Fechada | H24: 285000 | I24: Maio | J24: 2026
A25: 46165 | B25: Edifício Apex Tower | C25: Daniela Ramos | D25: Ana Souza | E25: Meta Ads | F25: R$ 850.000 | G25: 1. Lead | H25: - | I25: Maio | J25: 2026
A26: 46166 | B26: Condomínio Ville | C26: Gustavo Borges | D26: Roberto Lima | E26: Google Ads | F26: R$ 320.000 | G26: 3. Visita Agendada | H26: - | I26: Maio | J26: 2026
A27: 46166 | B27: Solar das Palmeiras | C27: Amanda Freitas | D27: Mariana Costa | E27: WhatsApp Direct | F27: R$ 680.000 | G27: 2. Contato Feito | H27: - | I27: Maio | J27: 2026
A28: 46166 | B28: Grand Valley Resort | C28: Leonardo Pires | D28: Lucas Mendes | E28: Indicação | F28: R$ 1.200.000 | G28: 5. Venda Fechada | H28: 1200000 | I28: Maio | J28: 2026
A29: 46169 | B29: Residencial Horizons | C29: Nicole Vasconcelos | D29: Carlos Silva | E29: Meta Ads | F29: R$ 450.000 | G29: 1. Lead | H29: - | I29: Maio | J29: 2026
A30: 46201 | B30: Horizon City | C30: Samuel Cardoso | D30: Juliana Paes | E30: Google Ads | F30: R$ 510.000 | G30: 1. Lead | H30: - | I30: Junho | J30: 2026

Sheet MÉTRICAS
A1: MÉTRICAS
A2: ID CLIENTE | B2: MÊS/ANO | C2: ANO | D2: TICKET EFETIVO | E2: VENDA FECHADA
A3: =Table14[[#This Row],[CLIENTE]] -> João Pedro Silva | B3: =TEXT(Table14[[#This Row],[DATA]],"mm/yy") -> 03/26 | C3: =YEAR(Table14[[#This Row],[DATA]]) -> 2026 | D3: =IF(BASE_DADOS!G3="5. Venda Fechada", VALUE(SUBSTITUTE(SUBSTITUTE(TEXT(BASE_DADOS!H3, "0"), "R$", ""), ".", "")), 0) -> 440000 | E3: =IF(BASE_DADOS!G3="5. Venda Fechada", 1, 0) -> 1
A4: =Table14[[#This Row],[CLIENTE]] -> Maria Clara Santos | B4: =TEXT(Table14[[#This Row],[DATA]],"mm/yy") -> 05/26 | C4: =YEAR(Table14[[#This Row],[DATA]]) -> 2026 | D4: =IF(BASE_DADOS!G4="5. Venda Fechada", VALUE(SUBSTITUTE(SUBSTITUTE(TEXT(BASE_DADOS!H4, "0"), "R$", ""), ".", "")), 0) -> 0 | E4: =IF(BASE_DADOS!G4="5. Venda Fechada", 1, 0) -> 0
A5: =Table14[[#This Row],[CLIENTE]] -> Lucas Oliveira | B5: =TEXT(Table14[[#This Row],[DATA]],"mm/yy") -> 05/26 | C5: =YEAR(Table14[[#This Row],[DATA]]) -> 2026 | D5: =IF(BASE_DADOS!G5="5. Venda Fechada", VALUE(SUBSTITUTE(SUBSTITUTE(TEXT(BASE_DADOS!H5, "0"), "R$", ""), ".", "")), 0) -> 0 | E5: =IF(BASE_DADOS!G5="5. Venda Fechada", 1, 0) -> 0
A6: =Table14[[#This Row],[CLIENTE]] -> Beatrys Rocha | B6: =TEXT(Table14[[#This Row],[DATA]],"mm/yy") -> 05/26 | C6: =YEAR(Table14[[#This Row],[DATA]]) -> 2026 | D6: =IF(BASE_DADOS!G6="5. Venda Fechada", VALUE(SUBSTITUTE(SUBSTITUTE(TEXT(BASE_DADOS!H6, "0"), "R$", ""), ".", "")), 0) -> 0 | E6: =IF(BASE_DADOS!G6="5. Venda Fechada", 1, 0) -> 0
A7: =Table14[[#This Row],[CLIENTE]] -> Gabriel Souza | B7: =TEXT(Table14[[#This Row],[DATA]],"mm/yy") -> 05/26 | C7: =YEAR(Table14[[#This Row],[DATA]]) -> 2026 | D7: =IF(BASE_DADOS!G7="5. Venda Fechada", VALUE(SUBSTITUTE(SUBSTITUTE(TEXT(BASE_DADOS!H7, "0"), "R$", ""), ".", "")), 0) -> 1150000 | E7: =IF(BASE_DADOS!G7="5. Venda Fechada", 1, 0) -> 1
A8: =Table14[[#This Row],[CLIENTE]] -> Patricia Lima | B8: =TEXT(Table14[[#This Row],[DATA]],"mm/yy") -> 05/26 | C8: =YEAR(Table14[[#This Row],[DATA]]) -> 2026 | D8: =IF(BASE_DADOS!G8="5. Venda Fechada", VALUE(SUBSTITUTE(SUBSTITUTE(TEXT(BASE_DADOS!H8, "0"), "R$", ""), ".", "")), 0) -> 0 | E8: =IF(BASE_DADOS!G8="5. Venda Fechada", 1, 0) -> 0
A9: =Table14[[#This Row],[CLIENTE]] -> Rodrigo Alves | B9: =TEXT(Table14[[#This Row],[DATA]],"mm/yy") -> 05/26 | C9: =YEAR(Table14[[#This Row],[DATA]]) -> 2026 | D9: =IF(BASE_DADOS!G9="5. Venda Fechada", VALUE(SUBSTITUTE(SUBSTITUTE(TEXT(BASE_DADOS!H9, "0"), "R$", ""), ".", "")), 0) -> 0 | E9: =IF(BASE_DADOS!G9="5. Venda Fechada", 1, 0) -> 0
A10: =Table14[[#This Row],[CLIENTE]] -> Camila Ribeiro | B10: =TEXT(Table14[[#This Row],[DATA]],"mm/yy") -> 05/26 | C10: =YEAR(Table14[[#This Row],[DATA]]) -> 2026 | D10: =IF(BASE_DADOS!G10="5. Venda Fechada", VALUE(SUBSTITUTE(SUBSTITUTE(TEXT(BASE_DADOS!H10, "0"), "R$", ""), ".", "")), 0) -> 0 | E10: =IF(BASE_DADOS!G10="5. Venda Fechada", 1, 0) -> 0
A11: =Table14[[#This Row],[CLIENTE]] -> Marcelo Castro | B11: =TEXT(Table14[[#This Row],[DATA]],"mm/yy") -> 05/26 | C11: =YEAR(Table14[[#This Row],[DATA]]) -> 2026 | D11: =IF(BASE_DADOS!G11="5. Venda Fechada", VALUE(SUBSTITUTE(SUBSTITUTE(TEXT(BASE_DADOS!H11, "0"), "R$", ""), ".", "")), 0) -> 0 | E11: =IF(BASE_DADOS!G11="5. Venda Fechada", 1, 0) -> 0
A12: =Table14[[#This Row],[CLIENTE]] -> Fernanda Gomes | B12: =TEXT(Table14[[#This Row],[DATA]],"mm/yy") -> 05/26 | C12: =YEAR(Table14[[#This Row],[DATA]]) -> 2026 | D12: =IF(BASE_DADOS!G12="5. Venda Fechada", VALUE(SUBSTITUTE(SUBSTITUTE(TEXT(BASE_DADOS!H12, "0"), "R$", ""), ".", "")), 0) -> 0 | E12: =IF(BASE_DADOS!G12="5. Venda Fechada", 1, 0) -> 0
A13: =Table14[[#This Row],[CLIENTE]] -> André Martins | B13: =TEXT(Table14[[#This Row],[DATA]],"mm/yy") -> 05/26 | C13: =YEAR(Table14[[#This Row],[DATA]]) -> 2026 | D13: =IF(BASE_DADOS!G13="5. Venda Fechada", VALUE(SUBSTITUTE(SUBSTITUTE(TEXT(BASE_DADOS!H13, "0"), "R$", ""), ".", "")), 0) -> 0 | E13: =IF(BASE_DADOS!G13="5. Venda Fechada", 1, 0) -> 0
A14: =Table14[[#This Row],[CLIENTE]] -> Vanessa Dias | B14: =TEXT(Table14[[#This Row],[DATA]],"mm/yy") -> 05/26 | C14: =YEAR(Table14[[#This Row],[DATA]]) -> 2026 | D14: =IF(BASE_DADOS!G14="5. Venda Fechada", VALUE(SUBSTITUTE(SUBSTITUTE(TEXT(BASE_DADOS!H14, "0"), "R$", ""), ".", "")), 0) -> 0 | E14: =IF(BASE_DADOS!G14="5. Venda Fechada", 1, 0) -> 0
... A30: =Table14[[#This Row],[CLIENTE]] -> Samuel Cardoso | B30: =TEXT(Table14[[#This Row],[DATA]],"mm/yy") -> 06/26 | C30: =YEAR(Table14[[#This Row],[DATA]]) -> 2026 | D30: =IF(BASE_DADOS!G30="5. Venda Fechada", VALUE(SUBSTITUTE(SUBSTITUTE(TEXT(BASE_DADOS!H30, "0"), "R$", ""), ".", "")), 0) -> 0 | E30: =IF(BASE_DADOS!G30="5. Venda Fechada", 1, 0) -> 0

Sheet APOIO
A1: CORRETOR(A) | B1: (All) | H1: {=CADASTRO!A3:A9} -> Residencial Horizons | I1: =SUMIFS(BASE_DADOS!$H:$H, BASE_DADOS!$B:$B, H1, BASE_DADOS!$I:$I, DASHBOARD!$H$2, BASE_DADOS!$J:$J, DASHBOARD!$J$2, BASE_DADOS!$G:$G, "5. Venda Fechada") -> 450000 | J1: =IFERROR(I1/INDICADORES!$B$7,0) -> 0.1458671 | K1: STATUS | L1: 5. Venda Fechada
H2: Edifício Apex Tower | I2: =SUMIFS(BASE_DADOS!$H:$H, BASE_DADOS!$B:$B, H2, BASE_DADOS!$I:$I, DASHBOARD!$H$2, BASE_DADOS!$J:$J, DASHBOARD!$J$2, BASE_DADOS!$G:$G, "5. Venda Fechada") -> 0 | J2: =IFERROR(I2/INDICADORES!$B$7,0) -> 0
A3: Row Labels | B3: Count of CLIENTE | E3: Row Labels | F3: Count of CLIENTE | H3: Condomínio Ville | I3: =SUMIFS(BASE_DADOS!$H:$H, BASE_DADOS!$B:$B, H3, BASE_DADOS!$I:$I, DASHBOARD!$H$2, BASE_DADOS!$J:$J, DASHBOARD!$J$2, BASE_DADOS!$G:$G, "5. Venda Fechada") -> 0 | J3: =IFERROR(I3/INDICADORES!$B$7,0) -> 0 | K3: Row Labels | L3: Count of CLIENTE | P3: Ranking de Corretor | Q3: Clientes | R3: VGV | S3: Venda Fechada | T3: Conversão
A4: 1. Lead | B4: 9 | E4: Google Ads | F4: 7 | H4: Solar das Palmeiras | I4: =SUMIFS(BASE_DADOS!$H:$H, BASE_DADOS!$B:$B, H4, BASE_DADOS!$I:$I, DASHBOARD!$H$2, BASE_DADOS!$J:$J, DASHBOARD!$J$2, BASE_DADOS!$G:$G, "5. Venda Fechada") -> 0 | J4: =IFERROR(I4/INDICADORES!$B$7,0) -> 0 | K4: Indicação | L4: 2 | P4: Ana Souza | Q4: 4 | R4: 0 | S4: 0 | T4: =IF(Q4="", "", IFERROR(S4/Q4, 0)) -> 0
A5: 2. Contato Feito | B5: 4 | E5: Indicação | F5: 5 | H5: Grand Valley Resort | I5: =SUMIFS(BASE_DADOS!$H:$H, BASE_DADOS!$B:$B, H5, BASE_DADOS!$I:$I, DASHBOARD!$H$2, BASE_DADOS!$J:$J, DASHBOARD!$J$2, BASE_DADOS!$G:$G, "5. Venda Fechada") -> 2350000 | J5: =IFERROR(I5/INDICADORES!$B$7,0) -> 0.76175041 | K5: Meta Ads | L5: 3 | P5: Carlos Silva | Q5: 5 | R5: 890000 | S5: 2 | T5: =IF(Q5="", "", IFERROR(S5/Q5, 0)) -> 0.4
A6: 3. Visita Agendada | B6: 4 | E6: Meta Ads | F6: 10 | H6: Horizon City | I6: =SUMIFS(BASE_DADOS!$H:$H, BASE_DADOS!$B:$B, H6, BASE_DADOS!$I:$I, DASHBOARD!$H$2, BASE_DADOS!$J:$J, DASHBOARD!$J$2, BASE_DADOS!$G:$G, "5. Venda Fechada") -> 0 | J6: =IFERROR(I6/INDICADORES!$B$7,0) -> 0 | K6: Grand Total | L6: 5 | P6: Fernando Dias | Q6: 3 | R6: 285000 | S6: 1 | T6: =IF(Q6="", "", IFERROR(S6/Q6, 0)) -> 0.33333333
A7: 4. Proposta Enviada | B7: 3 | E7: Passante / Placa | F7: 1 | H7: Villa Bella | I7: =SUMIFS(BASE_DADOS!$H:$H, BASE_DADOS!$B:$B, H7, BASE_DADOS!$I:$I, DASHBOARD!$H$2, BASE_DADOS!$J:$J, DASHBOARD!$J$2, BASE_DADOS!$G:$G, "5. Venda Fechada") -> 285000 | J7: =IFERROR(I7/INDICADORES!$B$7,0) -> 0.092382496 | P7: Juliana Paes | Q7: 4 | R7: 0 | S7: 0 | T7: =IF(Q7="", "", IFERROR(S7/Q7, 0)) -> 0
A8: 5. Venda Fechada | B8: 5 | E8: Portal Imobiliário | F8: 3 | P8: Lucas Mendes | Q8: 4 | R8: 2350000 | S8: 2 | T8: =IF(Q8="", "", IFERROR(S8/Q8, 0)) -> 0.5
A9: 6. Perdido | B9: 3 | E9: WhatsApp Direct | F9: 2 | P9: Mariana Costa | Q9: 4 | R9: 0 | S9: 0 | T9: =IF(Q9="", "", IFERROR(S9/Q9, 0)) -> 0
P10: Roberto Lima | Q10: 4 | R10: 0 | S10: 0 | T10: =IF(Q10="", "", IFERROR(S10/Q10, 0)) -> 0
S19: STATUS | T19: 3. Visita Agendada
S21: Row Labels | T21: Count of STATUS
N22: Mês | O22: (All) | S22: 46144 | T22: 1
N23: Ano | O23: (All) | S23: 46153 | T23: 1
S24: 46164 | T24: 1
N25: Row Labels | O25: Count of STATUS | S25: 46166 | T25: 1
N26: 46144 | O26: 4 | S26: Grand Total | T26: 4
N27: 46148 | O27: 1
N28: 46149 | O28: 1
N29: 46150 | O29: 1
N30: 46151 | O30: 1
N31: 46152 | O31: 1
A32: MÊS/ANO | B32: 05/26 | N32: 46153 | O32: 1
A33: ANO | B33: (All) | N33: 46154 | O33: 1
N34: 46155 | O34: 1
A35: Row Labels | N35: 46164 | O35: 9
A36: Amanda Freitas | N36: 46165 | O36: 1
A37: André Martins | N37: 46166 | O37: 3
A38: Beatrys Rocha | N38: 46169 | O38: 1
A39: Bruno Carvalho | N39: 46201 | O39: 1
A40: Caio Henrique | N40: Grand Total | O40: 27 | P40: Dias | Q40: Quantidade - total leads | R40: quantidade - visitas realizadas
A41: Camila Ribeiro | P41: 1 | Q41: =COUNTIFS(BASE_DADOS!$A:$A, DATE(DASHBOARD!$J$2, MATCH(DASHBOARD!$H$2, {"Janeiro","Fevereiro","Março","Abril","Maio","Junho","Julho","Agosto","Setembro","Outubro","Novembro","Dezembro"}, 0), M22)) -> 0
A42: Daniela Ramos | P42: 2 | Q42: =COUNTIFS(BASE_DADOS!$A:$A, DATE(DASHBOARD!$J$2, MATCH(DASHBOARD!$H$2, {"Janeiro","Fevereiro","Março","Abril","Maio","Junho","Julho","Agosto","Setembro","Outubro","Novembro","Dezembro"}, 0), M23)) -> 0
A43: Diego Fernandes | P43: 3 | Q43: =COUNTIFS(BASE_DADOS!$A:$A, DATE(DASHBOARD!$J$2, MATCH(DASHBOARD!$H$2, {"Janeiro","Fevereiro","Março","Abril","Maio","Junho","Julho","Agosto","Setembro","Outubro","Novembro","Dezembro"}, 0), M24)) -> 0
A44: Fabio Junqueira | P44: 4 | Q44: =COUNTIFS(BASE_DADOS!$A:$A, DATE(DASHBOARD!$J$2, MATCH(DASHBOARD!$H$2, {"Janeiro","Fevereiro","Março","Abril","Maio","Junho","Julho","Agosto","Setembro","Outubro","Novembro","Dezembro"}, 0), M25)) -> 0
A45: Fernanda Gomes | P45: 5 | Q45: =COUNTIFS(BASE_DADOS!$A:$A, DATE(DASHBOARD!$J$2, MATCH(DASHBOARD!$H$2, {"Janeiro","Fevereiro","Março","Abril","Maio","Junho","Julho","Agosto","Setembro","Outubro","Novembro","Dezembro"}, 0), M26)) -> 0
A46: Gabriel Souza | P46: 6 | Q46: =COUNTIFS(BASE_DADOS!$A:$A, DATE(DASHBOARD!$J$2, MATCH(DASHBOARD!$H$2, {"Janeiro","Fevereiro","Março","Abril","Maio","Junho","Julho","Agosto","Setembro","Outubro","Novembro","Dezembro"}, 0), M27)) -> 0
A47: Gustavo Borges | P47: 7 | Q47: =COUNTIFS(BASE_DADOS!$A:$A, DATE(DASHBOARD!$J$2, MATCH(DASHBOARD!$H$2, {"Janeiro","Fevereiro","Março","Abril","Maio","Junho","Julho","Agosto","Setembro","Outubro","Novembro","Dezembro"}, 0), M28)) -> 0
A48: Igor Barbosa | P48: 8 | Q48: =COUNTIFS(BASE_DADOS!$A:$A, DATE(DASHBOARD!$J$2, MATCH(DASHBOARD!$H$2, {"Janeiro","Fevereiro","Março","Abril","Maio","Junho","Julho","Agosto","Setembro","Outubro","Novembro","Dezembro"}, 0), M29)) -> 0
A49: Larissa Mello | P49: 9 | Q49: =COUNTIFS(BASE_DADOS!$A:$A, DATE(DASHBOARD!$J$2, MATCH(DASHBOARD!$H$2, {"Janeiro","Fevereiro","Março","Abril","Maio","Junho","Julho","Agosto","Setembro","Outubro","Novembro","Dezembro"}, 0), M30)) -> 0
...

Sheet INDICADORES
A1: INDICADORES
A2: INDICADOR | B2: VALOR
A3: Total Leads | B3: =IF(DASHBOARD!H2="Todos", COUNTIF(BASE_DADOS!A:A, ">0"), COUNTIFS(BASE_DADOS!A:A, ">="&DATE(DASHBOARD!J2, MATCH(DASHBOARD!H2, {"Janeiro","Fevereiro","Março","Abril","Maio","Junho","Julho","Agosto","Setembro","Outubro","Novembro","Dezembro"}, 0), 1), BASE_DADOS!A:A, "<="&EOMONTH(DATE(DASHBOARD!J2, MATCH(DASHBOARD!H2, {"Janeiro","Fevereiro","Março","Abril","Maio","Junho","Julho","Agosto","Setembro","Outubro","Novembro","Dezembro"}, 0), 1), 0))) -> 26
A4: Visitas Realizadas | B4: =IF(DASHBOARD!H2="Todos", COUNTIF(BASE_DADOS!G:G, "*Visita*"), COUNTIFS(BASE_DADOS!G:G, "*Visita*", BASE_DADOS!A:A, ">="&DATE(DASHBOARD!J2, MATCH(DASHBOARD!H2, {"Janeiro","Fevereiro","Março","Abril","Maio","Junho","Julho","Agosto","Setembro","Outubro","Novembro","Dezembro"}, 0), 1), BASE_DADOS!A:A, "<="&EOMONTH(DATE(DASHBOARD!J2, MATCH(DASHBOARD!H2, {"Janeiro","Fevereiro","Março","Abril","Maio","Junho","Julho","Agosto","Setembro","Outubro","Novembro","Dezembro"}, 0), 1), 0))) -> 4
A5: Propostas Enviadas | B5: =IF(DASHBOARD!H2="Todos", COUNTIF(BASE_DADOS!G:G, "*Proposta*"), COUNTIFS(BASE_DADOS!G:G, "*Proposta*", BASE_DADOS!A:A, ">="&DATE(DASHBOARD!J2, MATCH(DASHBOARD!H2, {"Janeiro","Fevereiro","Março","Abril","Maio","Junho","Julho","Agosto","Setembro","Outubro","Novembro","Dezembro"}, 0), 1), BASE_DADOS!A:A, "<="&EOMONTH(DATE(DASHBOARD!J2, MATCH(DASHBOARD!H2, {"Janeiro","Fevereiro","Março","Abril","Maio","Junho","Julho","Agosto","Setembro","Outubro","Novembro","Dezembro"}, 0), 1), 0))) -> 3
A6: Vendas Fechadas | B6: =IF(DASHBOARD!H2="Todos", COUNTIF(BASE_DADOS!G:G, "*Venda Fechada*"), COUNTIFS(BASE_DADOS!G:G, "*Venda Fechada*", BASE_DADOS!A:A, ">="&DATE(DASHBOARD!J2, MATCH(DASHBOARD!H2, {"Janeiro","Fevereiro","Março","Abril","Maio","Junho","Julho","Agosto","Setembro","Outubro","Novembro","Dezembro"}, 0), 1), BASE_DADOS!A:A, "<="&EOMONTH(DATE(DASHBOARD!J2, MATCH(DASHBOARD!H2, {"Janeiro","Fevereiro","Março","Abril","Maio","Junho","Julho","Agosto","Setembro","Outubro","Novembro","Dezembro"}, 0), 1), 0))) -> 4
A7: Faturamento | B7: =IF(DASHBOARD!H2="Todos", SUM(BASE_DADOS!H:H), SUMIFS(BASE_DADOS!H:H, BASE_DADOS!A:A, ">="&DATE(DASHBOARD!J2, MATCH(LEFT(DASHBOARD!H2, 4), {"Jane","Feve","Març","Abri","Maio","Junh","Julh","Agos","Sete","Outu","Nove","Deze"}, 0), 1), BASE_DADOS!A:A, "<="&EOMONTH(DATE(DASHBOARD!J2, MATCH(LEFT(DASHBOARD!H2, 4), {"Jane","Feve","Març","Abri","Maio","Junh","Julh","Agos","Sete","Outu","Nove","Deze"}, 0), 1), 0))) -> 3085000
A8: Ticket Médio | B8: =IF(B6>0, B7/B6, 0) -> 771250
A9: Taxa de Conversão (%) | B9: =IF(B3>0, B6/B3, 0) -> 0.15384615
A12: {=CADASTRO!D3:D8} -> Lead | B12: =COUNTIFS(BASE_DADOS!I:I, DASHBOARD!$H$2, BASE_DADOS!J:J, DASHBOARD!$J$2, BASE_DADOS!G:G, "*Lead*") -> 8
A13: Contato Feito | B13: =COUNTIFS(BASE_DADOS!I:I, DASHBOARD!$H$2, BASE_DADOS!J:J, DASHBOARD!$J$2, BASE_DADOS!G:G, "*Contato*") -> 4
A14: Visita Agendada | B14: =COUNTIFS(BASE_DADOS!I:I, DASHBOARD!$H$2, BASE_DADOS!J:J, DASHBOARD!$J$2, BASE_DADOS!G:G, "*Visita*") -> 4
A15: Proposta Enviada | B15: =COUNTIFS(BASE_DADOS!I:I, DASHBOARD!$H$2, BASE_DADOS!J:J, DASHBOARD!$J$2, BASE_DADOS!G:G, "*Proposta*") -> 3
A16: Venda Fechada | B16: =COUNTIFS(BASE_DADOS!I:I, DASHBOARD!$H$2, BASE_DADOS!J:J, DASHBOARD!$J$2, BASE_DADOS!G:G, "*Venda Fechada*") -> 4
A17: Perdido | B17: =COUNTIFS(BASE_DADOS!I:I, DASHBOARD!$H$2, BASE_DADOS!J:J, DASHBOARD!$J$2, BASE_DADOS!G:G, "*Perdido*") -> 3
A19: {=CADASTRO!C3:C9} -> Meta Ads | B19: =COUNTIFS(BASE_DADOS!I:I, DASHBOARD!$H$2, BASE_DADOS!J:J, DASHBOARD!$J$2, BASE_DADOS!E:E, A19) -> 9
A20: Google Ads | B20: =COUNTIFS(BASE_DADOS!I:I, DASHBOARD!$H$2, BASE_DADOS!J:J, DASHBOARD!$J$2, BASE_DADOS!E:E, A20) -> 6
A21: Portal Imobiliário | B21: =COUNTIFS(BASE_DADOS!I:I, DASHBOARD!$H$2, BASE_DADOS!J:J, DASHBOARD!$J$2, BASE_DADOS!E:E, A21) -> 3
A22: Indicação | B22: =COUNTIFS(BASE_DADOS!I:I, DASHBOARD!$H$2, BASE_DADOS!J:J, DASHBOARD!$J$2, BASE_DADOS!E:E, A22) -> 5
A23: Passante / Placa | B23: =COUNTIFS(BASE_DADOS!I:I, DASHBOARD!$H$2, BASE_DADOS!J:J, DASHBOARD!$J$2, BASE_DADOS!E:E, A23) -> 1
A24: WhatsApp Direct | B24: =COUNTIFS(BASE_DADOS!I:I, DASHBOARD!$H$2, BASE_DADOS!J:J, DASHBOARD!$J$2, BASE_DADOS!E:E, A24) -> 2
A25: Feira Imobiliária | B25: =COUNTIFS(BASE_DADOS!I:I, DASHBOARD!$H$2, BASE_DADOS!J:J, DASHBOARD!$J$2, BASE_DADOS!E:E, A25) -> 0
A28: Imóveis parados > 90 dias | B28: =COUNTIFS(BASE_DADOS!G:G, "<>Venda Fechada", BASE_DADOS!A:A, "<="&DATE(DASHBOARD!$J$2, MATCH(DASHBOARD!$H$2, {"Janeiro","Fevereiro","Março","Abril","Maio","Junho","Julho","Agosto","Setembro","Outubro","Novembro","Dezembro"}, 0), 1)-90) -> 0

Sheet DASHBOARD
C1: DASHBOARD CONF LIVING | H1: MÊS | J1: ANO
C2: IMOBILIÁRIA LTDA | H2: Maio | J2: 2026
C6: Total Leads | D6: Visitas Realizadas | F6: Vendas Fechadas | G6: Taxa de Conversão | I6: Imóveis parados >90 dias | K6: Faturamento
C29: Ranking de Corretor | D29: Clientes | E29: Valor Vendido | F29: Venda Fechada | G29: Conversão
C30: {=_xlfn.SORTBY(APOIO!A67:E73,APOIO!E67:E73,-1)} -> Lucas Mendes | D30: 4 | E30: 2350000 | F30: 2 | G30: 0.5
C31: Fernando Dias | D31: 3 | E31: 285000 | F31: 1 | G31: 0.33333333
C32: Carlos Silva | D32: 4 | E32: 450000 | F32: 1 | G32: 0.25
C33: Ana Souza | D33: 4 | E33: 0 | F33: 0 | G33: 0
C34: Roberto Lima | D34: 4 | E34: 0 | F34: 0 | G34: 0
C35: Mariana Costa | D35: 4 | E35: 0 | F35: 0 | G35: 0
C36: Juliana Paes | D36: 3 | E36: 0 | F36: 0 | G36: 0
